<?xml version="1.0" encoding="UTF-8" standalone="no" ?>
<robot name="test_robot">

  <link name="link1" >
   <collision>
     <origin xyz="3 0 0" rpy="0 0 0"/>
     <geometry>
       <box size="1 1 1"/>
     </geometry>
   </collision>
 </link>

  <link name="link2" >
   <collision>
     <origin xyz="-2 0 0" rpy="0 0 0"/>
     <geometry>
       <box size="1 1 1"/>
     </geometry>
   </collision>
 </link>


  <link name="link3" />
  <link name="link4" />

  <joint name="joint1" type="continuous">
    <parent link="link1"/>
    <child link="link2"/>
  </joint>

  <joint name="joint2" type="continuous">
    <parent link="link1"/>
    <child link="link3"/>
  </joint>

  <joint name="joint3" type="continuous">
    <parent link="link3"/>
    <child link="link4"/>
  </joint>

</robot>